Workbook

Sheet coofandy品类定价
A1: 一、COOFANDY 西装品类所有产品定价范围
A2: 指标名称 | C2: 线上商品平均售价(原币) $
A3: 五级品类 | B3: 平台 | C3: 2023-10 | D3: 2023-11 | E3: 2023-12 | F3: 2024-01 | G3: 2024-02 | H3: 2024-03 | I3: 2024-04 | J3: 2024-05 | K3: 2024-06 | L3: 2024-07 | M3: 2024-08 | N3: 2024-09 | O3: 平均售价$ | P3: 定价范围 $
A4: 西装上衣 | B4: Amazon | C4: 62.713584 | D4: 61.699373 | E4: 66.362429 | F4: 63.301432 | G4: 63.06213 | H4: 62.126371 | I4: 61.931043 | J4: 61.701383 | K4: 61.973514 | L4: 59.383001 | M4: 58.89572 | N4: 61.256587 | O4: =AVERAGEA(C4:N4) -> 62.03388 | P4: =ROUND(MIN(C4:N4),2)&"-"&ROUND(MAX(C4:N4),2) -> 58.9-66.36
B5: Shopify | C5: 58.013956 | D5: 57.764898 | E5: 62.668043 | F5: 58.613412 | G5: 61.750439 | H5: 60.791413 | I5: 59.433426 | J5: 60.038723 | K5: 60.609355 | L5: 59.590455 | M5: 59.115625 | N5: 56.315513 | O5: =AVERAGEA(C5:N5) -> 59.558771 | P5: =ROUND(MIN(C5:N5),2)&"-"&ROUND(MAX(C5:N5),2) -> 56.32-62.67
B6: Temu | J6: 44.99 | K6: 59.379091 | L6: 68.190927 | M6: 77.614382 | N6: 60.702716 | O6: =AVERAGEA(C6:N6) -> 62.175423 | P6: =ROUND(MIN(C6:N6),2)&"-"&ROUND(MAX(C6:N6),2) -> 44.99-77.61
B7: Tiktok | C7: 44.041818 | D7: 46.08 | E7: 58.38 | F7: 50.575 | G7: 40.43 | H7: 40.65087 | I7: 35.154151 | J7: 34.036855 | K7: 37.994727 | L7: 44.219333 | M7: 24.146122 | N7: 43.333 | O7: =AVERAGEA(C7:N7) -> 41.586823 | P7: =ROUND(MIN(C7:N7),2)&"-"&ROUND(MAX(C7:N7),2) -> 24.15-58.38
A8: 西装套装 | B8: Amazon | C8: 69.76011 | D8: 76.193911 | E8: 77.8137 | F8: 76.186175 | G8: 73.385956 | H8: 76.623074 | I8: 77.19145 | J8: 82.887741 | K8: 90.983535 | L8: 85.757804 | M8: 77.433025 | N8: 80.194747 | O8: =AVERAGEA(C8:N8) -> 78.700936 | P8: =ROUND(MIN(C8:N8),2)&"-"&ROUND(MAX(C8:N8),2) -> 69.76-90.98
B9: Shopify | C9: 79.89 | D9: 86.475909 | E9: 94.755 | F9: 77.312727 | G9: 75.255 | H9: 80.72129 | I9: 70.056786 | J9: 79.982857 | K9: 71.084884 | L9: 71.662742 | M9: 68.688276 | N9: 84.845714 | O9: =AVERAGEA(C9:N9) -> 78.394265 | P9: =ROUND(MIN(C9:N9),2)&"-"&ROUND(MAX(C9:N9),2) -> 68.69-94.76
B10: Temu | K10: 76.6075 | L10: 70.013687 | M10: 66.722752 | N10: 63.714522 | O10: =AVERAGEA(C10:N10) -> 69.264615 | P10: =ROUND(MIN(C10:N10),2)&"-"&ROUND(MAX(C10:N10),2) -> 63.71-76.61
B11: Tiktok | F11: 0 | G11: 0 | H11: 54.1675 | I11: 53.322083 | J11: 57.323962 | K11: 56.1864 | L11: 72.416 | M11: 71.23 | N11: 74.2325 | O11: =AVERAGEA(C11:N11) -> 48.764272 | P11: =ROUND(MIN(C11:N11),2)&"-"&ROUND(MAX(C11:N11),2) -> 0-74.23
A12: 西装马甲 | B12: Amazon | C12: 37.83379 | D12: 44.996146 | E12: 55.300783 | F12: 47.623487 | G12: 46.128905 | H12: 41.550648 | I12: 42.030475 | J12: 40.843645 | K12: 38.298496 | L12: 37.018161 | M12: 42.403366 | N12: 59.927189 | O12: =AVERAGEA(C12:N12) -> 44.496258 | P12: =ROUND(MIN(C12:N12),2)&"-"&ROUND(MAX(C12:N12),2) -> 37.02-59.93
B13: Shopify | C13: 35.012727 | D13: 33.759896 | E13: 33.571939 | F13: 36.113814 | G13: 35.472877 | H13: 34.642021 | I13: 34.591525 | J13: 35.697347 | K13: 33.940333 | L13: 35.204706 | M13: 36.037419 | N13: 36.438082 | O13: =AVERAGEA(C13:N13) -> 35.040224 | P13: =ROUND(MIN(C13:N13),2)&"-"&ROUND(MAX(C13:N13),2) -> 33.57-36.44
B14: Temu | K14: 23.441765 | L14: 16.245389 | M14: 12.586761 | N14: 17.347497 | O14: =AVERAGEA(C14:N14) -> 17.405353 | P14: =ROUND(MIN(C14:N14),2)&"-"&ROUND(MAX(C14:N14),2) -> 12.59-23.44
B15: Tiktok | F15: 13.778333 | G15: 16.74 | H15: 34.99 | I15: 30.956 | J15: 26.929 | K15: 25.744545 | L15: 27.003125 | M15: 30.569 | N15: 30.196667 | O15: =AVERAGEA(C15:N15) -> 26.322963 | P15: =ROUND(MIN(C15:N15),2)&"-"&ROUND(MAX(C15:N15),2) -> 13.78-34.99
B16: Walmart | N16: 37.88 | O16: =AVERAGEA(C16:N16) -> 37.88 | P16: =ROUND(MIN(C16:N16),2)&"-"&ROUND(MAX(C16:N16),2) -> 37.88-37.88
A17: 合计 | C17: 53.307199 | D17: 57.006446 | E17: 63.499328 | F17: 58.9158 | G17: 58.51023 | H17: 56.718672 | I17: 57.060503 | J17: 56.902601 | K17: 56.542233 | L17: 53.636257 | M17: 54.373829 | N17: 61.810178
A20: 过去12个月，coofany西装上衣平均定价在$58.9-$66.3， 均价在$62
A21: *淡季清仓的时候部分款式价格极低，所以这里数据采用平均数。
A24: 数据来源：BI
A25: 时间： 2024年10月8日过去12个月
A28: 二、 市场销量TOP100定价范围
A30: 西装外套类目下，top 100年销量的产品中，coofandy销量最具优势，前5个品牌大部分比coofandy便宜。 coofandy的均价在中间位置,价格段在$44-$65之间。
A31: 销量第二的PJ PAUL JONES价格段为$41.86-$74。 均价比coofandy均价高$2。
A32: Brand | B32: 求和项:Units Sold | C32: 平均值项:Avg. Listing Price | D32: 最小值项:Avg. Listing Price | E32: 最大值项:Avg. Listing Price
A33: COOFANDY | B33: 258494 | C33: 56.818182 | D33: 44.3 | E33: 64.74
A34: PJ PAUL JONES | B34: 210195 | C34: 59.367143 | D34: 41.86 | E34: 74.04
A35: Cloudstyle | B35: 95161 | C35: 49.13 | D35: 36.49 | E35: 65.07
A36: Beninos | B36: 50926 | C36: 35.63 | D36: 35.63 | E36: 35.63
A37: Mylldey | B37: 37084 | C37: 31.48 | D37: 31.48 | E37: 31.48
A38: MOGU | B38: 34939 | C38: 45.716667 | D38: 43.2 | E38: 47.75
A39: KUDORO | B39: 29946 | C39: 52.78 | D39: 45.76 | E39: 60.43
A40: GRACE KARIN | B40: 24735 | C40: 61.265 | D40: 60.13 | E40: 62.4
A41: P&L | B41: 24398 | C41: 71.143333 | D41: 68 | E41: 72.74
A42: Amazon Essentials | B42: 22375 | C42: 63.475 | D42: 58.34 | E42: 68.61
A43: MAGE MALE | B43: 17862 | C43: 60.513333 | D43: 59 | E43: 63.12
A44: YFFUSHI | B44: 17726 | C44: 42.496667 | D44: 29.62 | E44: 49.99
... A65: Datysum | B65: 3334 | C65: 47.84 | D65: 47.84 | E65: 47.84
A66: (空白)
A67: 总计 | B67: 989726 | C67: 55.9019 | D67: 29.62 | E67: 104.22
...

Sheet 西装-市场年销量TOP100产品定价
B1: Asin | C1: Variations | E1: Product | F1: Category | G1: Brand | H1: Units Sold | I1: Units Sold - Change | J1: Revenue | K1: Revenue - Change | L1: Product Views | M1: Views - Change | N1: Avg. Listing Price | O1: Reviews | P1: Rating | Q1: Badges | R1: Best Seller Rank | S1: Best Seller Category | X1: 西装外套类目下，top 100年销量的产品中，coofandy销量最具优势。 coofandy的均价在中间位置,价格段在$44-$65之间。销量第二的PJ PAUL JONES价格段为$41.86-$74, 均价比coofandy均价高$2.
B2: B07KWDH8HD | C2: B07KWN8S8H B07W72XFTG B085235FDF B083LXKFF8 B07W93LB84 B07WD4R2C7 B08911TN1P B087RQ6KS1 B07Z3B2WHB B07S9B8FQ3 | D2: ="amazon.com/dp/"&B2 -> amazon.com/dp/B07KWDH8HD | E2: COOFANDY Men's Blazer Casual Sport Coats Slim Fit One Button Suit Jacket Lightweight Sports Jacket | F2: 1045694 | G2: COOFANDY | H2: 89330 | I2: -0.27519534 | J2: 5531346 | K2: -0.31437179 | L2: 2281696 | M2: -0.25162814 | N2: 62 | O2: 9227 | P2: 4.1 | R2: 11 | S2: Clothing, Shoes & Jewelry > Men > Clothing > Suits & Sport Coats | X2: Brand | Y2: 求和项:Units Sold | Z2: 平均值项:Avg. Listing Price | AA2: 最小值项:Avg. Listing Price | AB2: 最大值项:Avg. Listing Price
B3: B085CLWCCN | C3: B01DWIFRA4 B00Z6XFV8C B01FR2382C B00Z6XFX4O B00Z6XFUU6 B00Z6XFUUQ B00Z6XFV3W B01FR238C2 B00Z6XG29Y B00Z6XG2G2 | E3: Beninos Mens Slim Fit Casual One Button Blazer Jacket | F3: 1045694 | G3: Beninos | H3: 50926 | I3: -0.051304024 | J3: 1809443 | K3: -0.03674742 | L3: 584255 | M3: -0.32704169 | N3: 35.63 | O3: 5837 | P3: 4.1 | R3: 1 | S3: Clothing, Shoes & Jewelry > Men > Clothing > Suits & Sport Coats > Sport Coats & Blazers | X3: COOFANDY | Y3: 258494 | Z3: 56.818182 | AA3: 44.3 | AB3: 64.74
B4: B073PYC4FS | C4: B073PY7WC9 B073PXSK2M B073PY3ZZZ B098HXL24D B073PY4DRJ B073PXL4PY B07CZY9Z2R B098J85YYZ B098J5JV1S B073PXM57H | E4: Cloudstyle Men's Suit Jacket One Button Slim Fit Sport Coat Business Daily Blazer | F4: 1045694 | G4: Cloudstyle | H4: 42429 | I4: -0.32415298 | J4: 1852236 | K4: -0.26196181 | L4: 709821 | M4: -0.075661232 | N4: 43.73 | O4: 5888 | P4: 4.1 | R4: 10 | S4: Clothing, Shoes & Jewelry > Men > Clothing > Suits & Sport Coats > Sport Coats & Blazers | X4: PJ PAUL JONES | Y4: 210195 | Z4: 59.367143 | AA4: 41.86 | AB4: 74.04
B5: B08S7JRS3P | C5: B08S6QF9FZ B0918XV2GM B08S6M99GF B08S6XWCN5 B08S7FCQC1 B0918ZGMC1 B08S7BVM2P B08S6XC78R B0BKZLR2QF B09ZDSLKCS | D5: ="www.amazon.com/dp/"&B5 -> www.amazon.com/dp/B08S7JRS3P | E5: PJ PAUL JONES Men's Casual Knit Blazer Suit Jackets Two Button Lightweight Unlined Sport Coat | F5: 1045694 | G5: PJ PAUL JONES | H5: 40276 | I5: 0.11824972 | J5: 2281232 | K5: 0.080520169 | L5: 822373 | M5: 0.32078196 | N5: 56.65 | O5: 2468 | P5: 4.1 | R5: 27 | S5: Clothing, Shoes & Jewelry > Men > Clothing > Suits & Sport Coats | X5: Cloudstyle | Y5: 95161 | Z5: 49.13 | AA5: 36.49 | AB5: 65.07
B6: B0CC4ZKYTL | C6: B0C8JHDVNW B0C8JFZMX9 B0C8JC2914 B0C8JDM55D B0C8JFKGJJ B0C8JGD92Y B0C8JHT1TS B0C8JF2T6P B0C8JFNR1Y B0C8JGSG5H | E6: Mylldey Mens Blazers Slim Fit Business Casual Men Suit Sport Coat One Button Travel Blazer Lightweight Suit Jacket | F6: 1045694 | G6: Mylldey | H6: 37084 | I6: 44.059538 | J6: 1163301 | K6: 43.126275 | L6: 405815 | M6: 75.195081 | N6: 31.48 | O6: 531 | P6: 4.1 | R6: 25 | S6: Clothing, Shoes & Jewelry > Men > Clothing > Suits & Sport Coats | X6: Beninos | Y6: 50926 | Z6: 35.63 | AA6: 35.63 | AB6: 35.63
B7: B08QJJCVVD | C7: B08QJJBF9X B08QJH6C72 B08QJJVYT5 B08QJJ9CJK B08QJHQLJS B08QJJD236 B097984PSG B08QJHNLVR B08QJJ5SNK B097988PFW | D7: ="www.amazon.com/dp/"&B7 -> www.amazon.com/dp/B08QJJCVVD | E7: PJ Paul Jones Men's Herringbone Blazer Jacket Lightweight Casual Knit Sport Coat | F7: 1045694 | G7: PJ PAUL JONES | H7: 32263 | I7: -0.04349244 | J7: 1835589 | K7: -0.099877603 | L7: 706811 | M7: 0.2128327 | N7: 56.93 | O7: 1721 | P7: 4.2 | R7: 14 | S7: Clothing, Shoes & Jewelry > Men > Clothing > Suits & Sport Coats > Sport Coats & Blazers | X7: Mylldey | Y7: 37084 | Z7: 31.48 | AA7: 31.48 | AB7: 31.48
B8: B0C5MVM3RT | C8: B0C5MWQ9SK B0C5MWDJSD B0C5MW98PJ B0C5MWML2Z B0CFL7H1X8 B0C5MS6QLD B0C5MTPZ21 B0C5MV6RNK B0CFL92W4W B0C5MVC5BL | D8: ="www.amazon.com/dp/"&B8 -> www.amazon.com/dp/B0C5MVM3RT | E8: PJ PAUL JONES Mens Casual Sport Coat Blazer Two Buttons Lightweight Business Jackets | F8: 1045694 | G8: PJ PAUL JONES | H8: 29454 | I8: 62.753247 | J8: 1655057 | K8: 77.864815 | L8: 579160 | M8: 94.303604 | N8: 56.41 | O8: 403 | P8: 4.2 | R8: 22 | S8: Clothing, Shoes & Jewelry > Men > Clothing > Suits & Sport Coats | X8: MOGU | Y8: 34939 | Z8: 45.716667 | AA8: 43.2 | AB8: 47.75
B9: B0CGHZTMQT | C9: B0CGJ19NF6 B0CGJ2LX56 B0CGJ2WHDM B0CGJ9RBBX B0CGJB6NHP B0CGJ4DJ7H B0CGJ2NNNN B0CGJC8DH5 B0CGJC1FHL B0CGWSY9QQ | D9: ="amazon.com/dp/"&B9 -> amazon.com/dp/B0CGHZTMQT | E9: COOFANDY Men's Blazer Casual Slim Fit Sport Coats Two Button Lightweight Suit Jacket | F9: 1045694 | G9: COOFANDY | H9: 22666 | J9: 1348628 | L9: 446893 | N9: 58.6 | O9: 399 | P9: 4.2 | R9: 23 | S9: Clothing, Shoes & Jewelry > Men > Clothing > Suits & Sport Coats > Sport Coats & Blazers | X9: KUDORO | Y9: 29946 | Z9: 52.78 | AA9: 45.76 | AB9: 60.43
B10: B0CBFXRGV4 | C10: B07QPT8FGK B07QRZTM2S B0841HP7SM B07QNQ9L95 B086884D5D B07QNQ8YNL B08R1Q4P82 B07R6L83YJ B08R1RNTXN B07PQSSVRQ | D10: ="amazon.com/dp/"&B10 -> amazon.com/dp/B0CBFXRGV4 | E10: COOFANDY Men's Tuxedo Jacket Wedding Blazer One Button Dress Suit for Dinner,Prom,Party | F10: 1045694 | G10: COOFANDY | H10: 22225 | I10: 14.728946 | J10: 1344400 | K10: 13.57123 | L10: 436857 | M10: 15.556394 | N10: 60.52 | P10: 4.2 | R10: 3 | S10: Clothing, Shoes & Jewelry > Men > Clothing > Suits & Sport Coats > Suit Separates > Suit Jackets | X10: GRACE KARIN | Y10: 24735 | Z10: 61.265 | AA10: 60.13 | AB10: 62.4
B11: B0B74XTXX8 | C11: B0B753RGSJ B0B74XX5DK B0B74YNL1F B0B74XWZBG B0B74X4GM7 B0B74P3KVK B0BRZZR222 B0CB13CC18 B0BHN3LW6C B0C39QPL95 | E11: GRACE KARIN Men's Casual Blazer Suit Jackets 2 Button Lightweight Sport Coats | F11: 1045694 | G11: GRACE KARIN | H11: 20948 | I11: 4.6190987 | J11: 1316778 | K11: 4.5896576 | L11: 454398 | M11: 5.7477168 | N11: 62.4 | O11: 523 | P11: 4.3 | R11: 39 | S11: Clothing, Shoes & Jewelry > Men > Clothing > Suits & Sport Coats | X11: P&L | Y11: 24398 | Z11: 71.143333 | AA11: 68 | AB11: 72.74
B12: B072PRRDHH | C12: B0187F205W B0187F270U B0187F25B6 B0187F28MW B071VYHL2S B0187F2AN4 B072FN2YVR B0187F2EDK B0187F2200 B0714J3643 | E12: Mens Blazer Slim Fit Sport Coats 26 Colors Suit Jacket for Daily Business and Prom Party | F12: 1045694 | G12: MOGU | H12: 20360 | I12: -0.14647439 | J12: 954646 | K12: -0.19655037 | L12: 212701 | M12: -0.36527438 | N12: 46.2 | O12: 2669 | P12: 4.3 | R12: 15 | S12: Clothing, Shoes & Jewelry > Men > Clothing > Suits & Sport Coats > Sport Coats & Blazers | X12: Amazon Essentials | Y12: 22375 | Z12: 63.475 | AA12: 58.34 | AB12: 68.61
B13: B09FFMMTKY | C13: B09FFNBRN6 B09FFKGYKX B09FFJM7D8 B09FFLJ7GN B09FFL51KY B09FFMVD57 B09FFKQWDY B09FFLB6PF B09FFM63ZC B09FFKRZ33 | D13: ="amazon.com/dp/"&B13 -> amazon.com/dp/B09FFMMTKY | E13: COOFANDY Mens Casual Blazer Sport Coat Slim Fit Two Button Suit Jackets Lightweight Business Sports Jacket | F13: 1045694 | G13: COOFANDY | H13: 19828 | I13: -0.027085378 | J13: 1187581 | K13: -0.080465938 | L13: 442344 | M13: 0.07275999 | N13: 59.09 | O13: 1280 | P13: 4 | R13: 53 | S13: Clothing, Shoes & Jewelry > Men > Clothing > Suits & Sport Coats > Sport Coats & Blazers | X13: MAGE MALE | Y13: 17862 | Z13: 60.513333 | AA13: 59 | AB13: 63.12
B14: B07RMM7MMM | C14: B07RK26MRQ B07RHXY6ZT B07RHXWD9Y B07RHXY7NL B07RHXY5T1 B07RMMHMP8 B07RL5WTR1 B07RM831JZ B07RGTQRZS B07RGTQQ4L | E14: Amazon Essentials Men's Long-Sleeve Classic-fit Button-Front Stretch Blazer | F14: 1045694 | G14: Amazon Essentials | H14: 16952 | I14: 0.94203231 | J14: 1099534 | K14: 0.80611217 | L14: 215309 | M14: -0.019772185 | N14: 68.61 | O14: 1028 | P14: 4.3 | R14: 25 | S14: Clothing, Shoes & Jewelry > Men > Clothing > Suits & Sport Coats > Sport Coats & Blazers | X14: YFFUSHI | Y14: 17726 | Z14: 42.496667 | AA14: 29.62 | AB14: 49.99
B15: B09XTLRZV5 | C15: B07TB2JC94 B07TC4RT8S B07TB2NXWH B07T82S83Q B07TB4VHKK B07TB439L6 B07TB526VR B07T96186N B07T82SMNB B07T82PQTP | E15: AMY ZHU Men's Sport Coat Classic Fit Stretch Blazer 2 Button Suit Jacket | F15: 1045694 | G15: AMY ZHU | H15: 14870 | I15: 0.1045907 | J15: 1062240 | K15: 0.034246062 | L15: 215020 | M15: 0.70951995 | N15: 71.57 | O15: 2183 | P15: 4.4 | R15: 11 | S15: Clothing, Shoes & Jewelry > Men > Clothing > Suits & Sport Coats > Sport Coats & Blazers | X15: AMY ZHU | Y15: 14870 | Z15: 71.57 | AA15: 71.57 | AB15: 71.57
B16: B0CP7S835J | C16: B00W6I427G B07FS8CM4Q B00W6I41ZE B00W6I424O B07FS81TJS B00W6I42CG B00W6I41XG B07FNBB4CL B07FN96JTN B00W6I41SQ | E16: P&L Men's Blazer Premium Stretch Classic Fit Sport Coat Suit Jacket | F16: 1045694 | G16: P&L | H16: 14834 | J16: 1083902 | L16: 243044 | N16: 72.69 | O16: 1594 | P16: 4.3 | R16: 12 | S16: Clothing, Shoes & Jewelry > Men > Clothing > Suits & Sport Coats > Sport Coats & Blazers | X16: Fxzpiodi | Y16: 13727 | Z16: 51.87 | AA16: 51.87 | AB16: 51.87
B17: B0743BZLW4 | C17: B01E9ZCR0W B01E9ZCT6E B01MXLKTKM B01E9ZCRN4 B0768VKSKT B01E9ZCWR0 B01N1FMTQU B0768VVGGP B01E9ZCUWC B01N418ANT | E17: Cloudstyle Men's Dress Floral Suit Notched Lapel Slim Fit Stylish Blazer Dress Suit | F17: 1045694 | G17: Cloudstyle | H17: 14668 | I17: -0.03860523 | J17: 856492 | K17: -0.088666696 | L17: 198146 | M17: 0.078069827 | N17: 57.94 | O17: 5191 | P17: 4.3 | R17: 35 | S17: Clothing, Shoes & Jewelry > Men > Clothing > Suits & Sport Coats > Sport Coats & Blazers | X17: Teemlanny | Y17: 13083 | Z17: 72.22 | AA17: 72.22 | AB17: 72.22
B18: B08PVV6F4R | C18: B0869GQYN6 B0869FT15K B07WBXSHTB B0869GL3HB B07W4N9HPT B07W5SFQFP B07W7X3D1S B0869GL9F4 B07WC1JV4V B07W6SQXXN | E18: Cloudstyle Mens Casual Slim Fit Suit Jacket 1 Button Daily Blazer Business Sport Coat Tops | F18: 1045694 | G18: Cloudstyle | H18: 14654 | I18: -0.23116474 | J18: 543764 | K18: -0.22685018 | L18: 191895 | M18: -0.10633869 | N18: 36.49 | O18: 1713 | P18: 3.9 | R18: 19 | S18: Clothing, Shoes & Jewelry > Men > Clothing > Suits & Sport Coats > Sport Coats & Blazers | X18: DAVID.ANN | Y18: 11795 | Z18: 36.95 | AA18: 34.9 | AB18: 39
B19: B09DPC7J69 | C19: B09DPM77ZW B09J4V1VNT B09DNZPDPQ B09DNVCPMF B09DPC9NMW B09DP9155Q B09DNQ6KWJ B09DNZVQCB B09DNS2Z4R B09DNVLPZ8 | D19: ="amazon.com/dp/"&B19 -> amazon.com/dp/B09DPC7J69 | E19: COOFANDY Men's Casual Linen Blazer Lightweight Regular Fit Sport Coat One Button Suit Jacket | F19: 1045694 | G19: COOFANDY | H19: 14585 | I19: -0.1828216 | J19: 745986 | K19: -0.32546237 | L19: 284128 | M19: -0.12457481 | N19: 53.36 | O19: 1171 | P19: 3.8 | R19: 84 | S19: Clothing, Shoes & Jewelry > Men > Clothing > Suits & Sport Coats > Sport Coats & Blazers | X19: Catheive | Y19: 11558 | Z19: 41.115 | AA19: 34.18 | AB19: 48.05
B20: B082K7P4VF | C20: B08R73ZYBQ B09289QRC9 B09289NFYX B09289ZW3P B08R759THS B08R72VCTZ B0989L3Y5Q B09KY7V3J3 B09YD8B7C5 B08R74JRSF | D20: ="www.amazon.com/dp/"&B20 -> www.amazon.com/dp/B082K7P4VF | E20: PJ Paul Jones Men's Casual One Button Suit Blazer Jacket Sport Coat | F20: 1045694 | G20: PJ PAUL JONES | H20: 14503 | I20: -0.39487629 | J20: 821203 | K20: -0.39692279 | L20: 263837 | M20: -0.38423173 | N20: 57.17 | O20: 1933 | P20: 4.1 | R20: 43 | S20: Clothing, Shoes & Jewelry > Men > Clothing > Suits & Sport Coats > Sport Coats & Blazers | X20: WEEN CHARM | Y20: 11312 | Z20: 64.13 | AA20: 64.13 | AB20: 64.13
B21: B0CP29C11T | C21: B0C6DYPLB1 B0CP5JNDG3 B0C5WMRHHR B0CX1HZKDF B0CX15M862 B0C6DZFLCV | E21: Mens Suit Jackets Casual Two Button Slim Fit Blazers Suit Separates Coat Sport Coats with Pockets for Wedding Prom Party | F21: 1045694 | G21: Fxzpiodi | H21: 13727 | J21: 715584 | L21: 232828 | N21: 51.87 | O21: 238 | P21: 3.9 | X21: THWEI | Y21: 11169 | Z21: 62.375 | AA21: 57.28 | AB21: 67.47
B22: B09R35TM93 | C22: B08K8CTGW3 B08DFYS56K B08DFYHQ3F B08DFZ5J6V B09VH3YW6W B08DFYQ545 B08DFYPRX6 B08DFXXDZ8 B08DFWTY2Z B0BHYRBR8F | E22: Men's Sport Coat Blazer Classic Fit 2 Button Notch Lapel Business Suits Jacket | F22: 1045694 | G22: Teemlanny | H22: 13083 | I22: 0.75375335 | J22: 950618 | K22: 0.68655149 | L22: 151830 | M22: 1.1011334 | N22: 72.22 | O22: 571 | P22: 4.4 | R22: 47 | S22: Clothing, Shoes & Jewelry > Men > Clothing > Suits & Sport Coats > Sport Coats & Blazers | X22: Haggar | Y22: 10451 | Z22: 86.633333 | AA22: 65.03 | AB22: 104.22
A23: =_xlfn.XLOOKUP(B23,[1]组件!$A:$A,[1]组件!$D:$D) -> #N/A | B23: B09VGT152F | C23: B09P3D88MR B09P3LC8P1 B09P2WLBN9 B09P343KT9 B09SV555H5 B09P32JQ27 B09SV47D6D B09SV25HFW B09SV259HB B09JGK37XC | E23: Mens Plaid Blazer Sports Coat Casual Slim Fit Checkered Blazer for Men Wedding | F23: 1045694 | G23: KUDORO | H23: 12313 | I23: 0.20869736 | J23: 733654 | K23: 0.30726946 | L23: 289233 | M23: 0.66061709 | N23: 60.43 | O23: 740 | P23: 4.2 | R23: 30 | S23: Clothing, Shoes & Jewelry > Men > Clothing > Suits & Sport Coats > Sport Coats & Blazers | X23: KUDMOL | Y23: 8248 | Z23: 47.54 | AA23: 43.59 | AB23: 51.49
A24: =_xlfn.XLOOKUP(B24,[1]组件!$A:$A,[1]组件!$D:$D) -> #N/A | B24: B0BQXCRRPD | C24: B0B5WZWQMM B0B5X21KDC B0B5X1YBK5 B0B5WZGLC7 B0B5X25XSH B0BKZLC4H6 B0B5X19J14 B0B5WYK2GQ B0B5WYNY13 B0B5X263CD | D24: ="www.amazon.com/dp/"&B24 -> www.amazon.com/dp/B0BQXCRRPD | E24: Mens Lightweight Notch Lapels Sport Coats Regular Fit Unlined Knit Blazer Jacket XXL | F24: 1045694 | G24: PJ PAUL JONES | H24: 11463 | I24: 1.4747409 | J24: 636014 | K24: 1.387207 | L24: 149869 | M24: 1.1118125 | N24: 55 | O24: 2468 | P24: 4.1 | X24: UNINUKOO | Y24: 7856 | Z24: 45.125 | AA24: 44.75 | AB24: 45.5
A25: =_xlfn.XLOOKUP(B25,[1]组件!$A:$A,[1]组件!$D:$D) -> #N/A | B25: B07WG5ST32 | C25: B07WKDQ6DZ B07WH5WR4X B07WJ8XSYJ B07WKDNCQ1 B07WN6DV81 B07WG5RDSG B07WG5S3PR B07WJ8Y58M B09QKPDFDL B09QKWRXXF | E25: WEEN CHARM Velvet Blazer for Men Slim Fit One Button Sport Coat Tuxedo Jacket for Prom Wedding Party Dinner | F25: 1045694 | G25: WEEN CHARM | H25: 11312 | I25: 0.39327503 | J25: 700311 | K25: 0.26989173 | L25: 179687 | M25: 0.43914238 | N25: 64.13 | O25: 1261 | P25: 4.3 | X25: KISSQIQI | Y25: 6620 | Z25: 52.84 | AA25: 52.84 | AB25: 52.84
A26: =_xlfn.XLOOKUP(B26,[1]组件!$A:$A,[1]组件!$D:$D) -> #N/A | B26: B0CM6HV6Z4 | C26: B0BDDYBTJ4 B0BDD1FP5C B0BDD1H81B B0BDDM151S B0BDD55JFJ B0BP1G6SWW B0BKFXYMFT B0BDDPY4X4 B0C5R1RCSJ B0BQXNQL4M | D26: ="amazon.com/dp/"&B26 -> amazon.com/dp/B0CM6HV6Z4 | E26: COOFANDY Men's Linen Cotton Casual Suits Blazer Jackets Lightweight Sports Coats | F26: 1045694 | G26: COOFANDY | H26: 10571 | J26: 484436 | L26: 237719 | N26: 46.48 | O26: 364 | P26: 2.8 | R26: 60 | S26: Clothing, Shoes & Jewelry > Men > Clothing > Suits & Sport Coats > Sport Coats & Blazers | X26: chouyatou | Y26: 6140 | Z26: 57.33 | AA26: 57.33 | AB26: 57.33
A27: =_xlfn.XLOOKUP(B27,[1]组件!$A:$A,[1]组件!$D:$D) -> #N/A | B27: B082HQJTZP | C27: B082HQG5ZG B082HRM4C9 B082HPP6MC B082HR2B6H B082HQT89P B08CB9JC71 B082HR4SBP B08CB84GQQ B082HQCQVC B09ZV2FHYX | D27: ="www.amazon.com/dp/"&B27 -> www.amazon.com/dp/B082HQJTZP | E27: PJ Paul Jones Men's Slim Fit Lightweight Linen Jacket Tailored Blazer Sport Coat | F27: 1045694 | G27: PJ PAUL JONES | H27: 10164 | I27: -0.5852275 | J27: 600292 | K27: -0.57877615 | L27: 218389 | M27: -0.4595442 | N27: 59.2 | O27: 1704 | P27: 4 | R27: 75 | S27: Clothing, Shoes & Jewelry > Men > Clothing > Suits & Sport Coats > Sport Coats & Blazers | X27: Hi-Tie | Y27: 5980 | Z27: 83.37 | AA27: 83.37 | AB27: 83.37
A28: =_xlfn.XLOOKUP(B28,[1]组件!$A:$A,[1]组件!$D:$D) -> #N/A | B28: B0CJRMVT8G | C28: B07SY7WYR2 B07XCN9FXP B0B1TF2VM9 B07SSXGY1R B07RP6NGVK B07XCLVTJV B07SX73TDT B08PPGQ1BQ B07X7VVCG4 B07SYPP6TS | D28: ="amazon.com/dp/"&B28 -> amazon.com/dp/B0CJRMVT8G | E28: COOFANDY Men's Slim Fit Casual Blazers Lightweight Sport Coats One Button Suit Jackets | F28: 1045694 | G28: COOFANDY | H28: 9927 | J28: 574989 | L28: 220921 | N28: 60.97 | O28: 1506 | P28: 4.2 | R28: 56 | S28: Clothing, Shoes & Jewelry > Men > Clothing > Suits & Sport Coats > Sport Coats & Blazers | X28: YUNCLOS | Y28: 5940 | Z28: 37.61 | AA28: 37.61 | AB28: 37.61
A29: =_xlfn.XLOOKUP(B29,[1]组件!$A:$A,[1]组件!$D:$D) -> #N/A | B29: B08CRQDD1Z | C29: B08CRDJCC9 B08CR32JM1 B08CRC3M46 B08CRLMXY5 B08CRCN6L2 B08CRS6HMG B08CR36X3D B08CR6R26S B08CR5MLBB B08KP4MLJF | D29: ="www.amazon.com/dp/"&B29 -> www.amazon.com/dp/B08CRQDD1Z | E29: Herringbone Tweed Blazer British Wool Blend Sport Coat Jacket | F29: 1045694 | G29: PJ PAUL JONES | H29: 9789 | I29: 0.55727012 | J29: 666933 | K29: 0.40022549 | L29: 198303 | M29: 0.25447886 | N29: 70.85 | O29: 1134 | P29: 4.2 | R29: 43 | S29: Clothing, Shoes & Jewelry > Men > Clothing > Suits & Sport Coats | X29: Aowdoy | Y29: 5311 | Z29: 49.27 | AA29: 49.27 | AB29: 49.27
A30: =_xlfn.XLOOKUP(B30,[1]组件!$A:$A,[1]组件!$D:$D) -> #N/A | B30: B0855RQ7NH | C30: B07T3K3ZKD B07ZBDWG21 B07T2HHPZC B07T4N76SD B07T1JR661 B07T6SWRYW B07SZCSTG5 B07T1HZMXF B07T4Q9CRG B07T3J9G26 | E30: Men's Casual Suit Jacket Slim Fit One Button Notched Lapel Business Daily Lightweight Blazer Jacket | F30: 1045694 | G30: YFFUSHI | H30: 9245 | I30: 0.18738762 | J30: 273972 | K30: 0.2266927 | L30: 103409 | M30: 0.11480164 | N30: 29.62 | O30: 941 | P30: 3.6 | R30: 44 | S30: Clothing, Shoes & Jewelry > Men > Clothing > Suits & Sport Coats > Sport Coats & Blazers | X30: Lion Nardo | Y30: 4242 | Z30: 47.85 | AA30: 47.85 | AB30: 47.85
A31: =_xlfn.XLOOKUP(B31,[1]组件!$A:$A,[1]组件!$D:$D) -> #N/A | B31: B07YDJKWB5 | C31: B08FX4MCYR B07YDHG7PW B07YDJVCQK B07YDJ8S2J B07YDJ3YBX B07YDJVD85 B092MBNSMF B094Y7C62Z B08ZDKL7ML B09M3PN9K3 | D31: ="amazon.com/dp/"&B31 -> amazon.com/dp/B07YDJKWB5 | E31: COOFANDY Men's Floral Tuxedo Jacket Jacquard Suit Jacket Slim Fit Blazer for Wedding, Prom, Dinner | F31: 1045694 | G31: COOFANDY | H31: 8786 | I31: 0.063680387 | J31: 531549 | K31: 0.0052746047 | L31: 125110 | M31: 0.10298072 | N31: 59.32 | O31: 971 | P31: 4.4 | R31: 14 | S31: Clothing, Shoes & Jewelry > Men > Clothing > Suits & Sport Coats > Tuxedos | X31: SISAVE | Y31: 4009 | Z31: 48.66 | AA31: 48.66 | AB31: 48.66
A32: =_xlfn.XLOOKUP(B32,[1]组件!$A:$A,[1]组件!$D:$D) -> #N/A | B32: B07TZ1FWCM | C32: B07ZJ5ZW4D B07TZNLVSN B07ZJ5ZWTQ B0B939WF8V B07TWTN7WF B0B938FMFB B0B936ZV37 B08KT7VXTH B07TZ251LC B0B93BJ6RK | D32: ="www.amazon.com/dp/"&B32 -> www.amazon.com/dp/B07TZ1FWCM | E32: PJ PAUL JONES Men's Cardigan Sweater Shawl Collar Button Down Knit Blazer Jacket Knitwear | F32: 1045694 | G32: PJ PAUL JONES | H32: 8178 | I32: 0.41072969 | J32: 332894 | K32: 0.70561804 | L32: 100977 | M32: 1.2009416 | N32: 41.86 | O32: 778 | P32: 4.2 | R32: 28 | S32: Clothing, Shoes & Jewelry > Men > Clothing > Sweaters > Cardigans | X32: Blissshow | Y32: 3509 | Z32: 59.74 | AA32: 59.74 | AB32: 59.74
A33: =_xlfn.XLOOKUP(B33,[1]组件!$A:$A,[1]组件!$D:$D) -> #N/A | B33: B07KXL9G53 | C33: B07KXMYXQ9 B07KXM73K9 B07KXPVSCS B0986WNLKR B07KXLLHMZ B07KXLW635 B07KXMMZDS B07KXM7SZ3 B07KXPK3QK B07KXM9YVD | E33: Cloudstyle Mens One Button Sequin Dress Suit Jacket Party Festival Tuxedo Sport Coat | F33: 1045694 | G33: Cloudstyle | H33: 7916 | I33: 0.80565693 | J33: 389800 | K33: 0.79681846 | L33: 80983 | M33: 0.6151054 | N33: 49.19 | O33: 564 | P33: 4.2 | R33: 38 | S33: Clothing, Shoes & Jewelry > Men > Clothing > Suits & Sport Coats > Sport Coats & Blazers | X33: Lynerun | Y33: 3366 | Z33: 48.88 | AA33: 48.88 | AB33: 48.88
A34: =_xlfn.XLOOKUP(B34,[1]组件!$A:$A,[1]组件!$D:$D) -> #N/A | B34: B07GBSJP2N | C34: B07GBTYVPR B07GBTPGT5 B07GBSP457 B07GBV8KTH B07GBTTXYX B07GBTGVHC B07GBW1HBY B08B18S8NL B07GBV11TF B07GBSDZP6 | E34: Mens Suit Jacket Slim Fit Sport Coats Blazer for Daily Business Wedding Party | F34: 1045694 | G34: MOGU | H34: 7832 | I34: -0.13601765 | J34: 375441 | K34: -0.14965675 | L34: 78128 | M34: -0.26036864 | N34: 47.75 | O34: 1301 | P34: 4.2 | R34: 52 | S34: Clothing, Shoes & Jewelry > Men > Clothing > Suits & Sport Coats > Sport Coats & Blazers | X34: J.Ver | Y34: 3365 | Z34: 42.96 | AA34: 42.96 | AB34: 42.96
A35: =_xlfn.XLOOKUP(B35,[1]组件!$A:$A,[1]组件!$D:$D) -> #N/A | B35: B0B7X9XRTW | C35: B0B7XB58QX B0B7X8856R B0B7X8ZTD7 B0B7X8BMMM B0B7X7L35N B0B7X8W7TW B0B7XBCJX9 B0B7X8NBMR B0B7X7B92L B0B7X89Z6T | E35: Mens Velvet Blazer Slim Fit Suit Jacket for Men Peaked Lapel One Button Tuxedo Blazer Wedding Prom Dinner | F35: 1045694 | G35: KUDORO | H35: 7561 | I35: 3.4061772 | J35: 382138 | K35: 3.6442478 | L35: 91113 | M35: 5.626882 | N35: 50.37 | O35: 236 | P35: 4.4 | R35: 42 | S35: Clothing, Shoes & Jewelry > Men > Clothing > Suits & Sport Coats > Sport Coats & Blazers | X35: Datysum | Y35: 3334 | Z35: 47.84 | AA35: 47.84 | AB35: 47.84
A36: =_xlfn.XLOOKUP(B36,[1]组件!$A:$A,[1]组件!$D:$D) -> #N/A | B36: B09MQHW1QM | C36: B09QRLDL63 B09KKMQQDG B09QS3YTJY B09QS3MQ92 B09KLDPHKQ B09QRW4DLT B09QRPXVMM B09QRT1VSZ B09MKC99F5 B09QRM9XBD | E36: MAGE MALE Men's Slim Fit Blazer Jackets Suit One Button Lightweight Sport Coats Casual Blazer | F36: 1045694 | G36: MAGE MALE | H36: 7140 | I36: -0.14058739 | J36: 400890 | K36: -0.20704715 | L36: 112480 | M36: 0.094568031 | N36: 59.42 | O36: 786 | P36: 4 | X36: (空白)
A37: =_xlfn.XLOOKUP(B37,[1]组件!$A:$A,[1]组件!$D:$D) -> #N/A | B37: B07CJKY9ZG | C37: B075Q66TKL B01MZ58QYD B01N0WAUPS B07ZM1JMZ7 B07ZLZ9B1R B07ZLZPNW7 B07ZLZ8G87 B01N2ZC66A B01N1XRVIZ B07ZLZNQST | E37: DAVID.ANN Men's Slim Fit One Button Casual Blazer Jacket | F37: 1045694 | G37: DAVID.ANN | H37: 6830 | I37: 0.33450567 | J37: 239690 | K37: 0.41678341 | L37: 69676 | M37: 0.11712174 | N37: 34.9 | O37: 797 | P37: 4 | R37: 69 | S37: Clothing, Shoes & Jewelry > Men > Clothing > Suits & Sport Coats > Sport Coats & Blazers | X37: 总计 | Y37: 989726 | Z37: 55.9019 | AA37: 29.62 | AB37: 104.22
A38: =_xlfn.XLOOKUP(B38,[1]组件!$A:$A,[1]组件!$D:$D) -> #N/A | B38: B0C5WS2T12 | C38: B0C5WVGVCM B0C5WVXJ2L B0C5WTJYZW B0C5WT5G11 B0C5WWH6HC B0C5WT2KDV B0C5WVS5ZF B0C5WX4K8J B0C5WVQNHW B0C5WW78T4 | D38: ="amazon.com/dp/"&B38 -> amazon.com/dp/B0C5WS2T12 | E38: COOFANDY Men's Casual Blazer Jacket One Button Suit Jackets Lightweight Knit Sport Coat | F38: 1045694 | G38: COOFANDY | H38: 6817 | I38: 7.6840764 | J38: 400623 | K38: 7.6850286 | L38: 142102 | M38: 13.184668 | N38: 59.71 | O38: 178 | P38: 4
A39: =_xlfn.XLOOKUP(B39,[1]组件!$A:$A,[1]组件!$D:$D) -> #N/A | B39: B0193DYCTY | C39: B099ZP64GL B099ZLRTGJ B099ZMKLFN B09B14DVNS B099ZN4CLL B099ZN5QD9 B099ZNHMT1 B099ZNBQDQ B09Z6GR5G2 B09Z67KHF1 | E39: MOGU Men's Casual Suit Blazer Jackets Slim Fit Plaid Sports Coat | F39: 1045694 | G39: MOGU | H39: 6747 | I39: 0.63921283 | J39: 295032 | K39: 0.30708229 | L39: 76328 | M39: 0.29833812 | N39: 43.2 | O39: 211 | P39: 4.3
A40: =_xlfn.XLOOKUP(B40,[1]组件!$A:$A,[1]组件!$D:$D) -> #N/A | B40: B0968MBMQX | C40: B07PR7H66K B08YXTS83T B07PS9BTDD B07PS8PB4W B07PSBPDHC B07PSBL11B B0968NQBSX B0968NZTRQ B07PSBM35S B07PMZZ421 | E40: Men's Blazer Lightweight Casual Solid One Button Slim Fit Sport Coat | F40: 1045694 | G40: Catheive | H40: 6656 | I40: -0.13513514 | J40: 230734 | K40: -0.14902892 | L40: 79639 | M40: -0.060882998 | N40: 34.18 | O40: 670 | P40: 3.7 | R40: 68 | S40: Clothing, Shoes & Jewelry > Men > Clothing > Suits & Sport Coats > Sport Coats & Blazers
...

Sheet 夹克-市场年销量TOP100定价
A1: 夹克市场颗粒度大，其中包含很多细分品类，因此价格差异大。 coofandy的价位在这100个畅销款中在中下位置，相对便宜。 价格段$27-$45.6。 | K1: Asin | L1: Variations | M1: Product | N1: Category | O1: Brand | P1: Units Sold | Q1: Units Sold - Change | R1: Revenue | S1: Revenue - Change | T1: Product Views | U1: Views - Change | V1: Avg. Listing Price | W1: Reviews | X1: Rating | Y1: Badges | Z1: Best Seller Rank | AA1: Best Seller Category | AB1: Amazons Choice Keyword | AC1: Prime | AD1: Climate Pledge Friendly | AE1: Amazon brand | AF1: Amazon Exclusive | AG1: Small Business
A2: Brand | B2: 求和项:Units Sold | C2: 平均值项:Avg. Listing Price | D2: 最小值项:Avg. Listing Price | E2: 最大值项:Avg. Listing Price | K2: B095HF44HC | L2: B095HF44HC | M2: Hagon PRO Disposable Rain Ponchos for Adults (5 Pack) | N2: 2476604011 | O2: Hagon PRO | P2: 250165 | Q2: 1.3134722 | R2: 3063717 | S2: 1.2467956 | T2: 1525204 | U2: 0.5917204 | V2: 12.29 | X2: 4.4
A3: Amazon Essentials | B3: 620329 | C3: 22.7875 | D3: 8.78 | E3: 42.34 | K3: B0738J92CM | L3: B073G9YNBR B0738H6TFC B073GGQ2VN B073GCH3WK B0738KW646 B0738GM37C B0738HBW7N B079LNQMC1 B0738G223R B085Z1YNDW | M3: Amazon Essentials Men's Full-Zip Fleece Jacket (Available in Big & Tall) | N3: 2476496011 | O3: Amazon Essentials | P3: 228939 | Q3: 0.1260255 | R3: 3536207 | S3: -0.051337198 | T3: 3897678 | U3: 0.043621242 | V3: 15.05 | W3: 13643 | X3: 4.5 | AC3: TRUE
A4: Columbia | B4: 491383 | C4: 52.59875 | D4: 29.08 | E4: 82.9 | K4: B01L0KQ1WO | L4: B01L0KX334 B01L0KWZ1A | M4: Wrangler Authentics Men's Long Sleeve Fleece Quarter-Zip | N4: 2476496011 | O4: Wrangler | P4: 163695 | Q4: 0.067341736 | R4: 4199675 | S4: 0.086845972 | T4: 1478779 | U4: -0.2516721 | V4: 25.68 | W4: 24444 | X4: 4.5
A5: Hagon PRO | B5: 275291 | C5: 11.96 | D5: 11.63 | E5: 12.29 | K5: B09LLL3RF3 | L5: B09LLW2Q4R B09LLRLNSK B09LLPGMW8 B09LLHRW4X B09LLQ8W6M B09LLHQKN3 B0C6XBWPQH B0BW43BR9B B09LM5GWDG B09LLVW8Q8 | M5: PTEROMY Hooded Rain Poncho for Adult with Pocket, Waterproof Lightweight Unisex Raincoat for Hiking Camping Emergency | N5: 2476604011 | O5: PTEROMY | P5: 157856 | Q5: 0.86388325 | R5: 2848505 | S5: 0.90475315 | T5: 1590767 | U5: 1.012274 | V5: 18.18 | W5: 7353 | X5: 4.6 | Z5: 1 | AA5: Clothing, Shoes & Jewelry > Men > Clothing > Jackets & Coats > Trench & Rain | AC5: TRUE
A6: Wrangler | B6: 236632 | C6: 27.51 | D6: 25.68 | E6: 29.34 | K6: B0C8KPCKYM | L6: B006WHHX5U B006WHHX46 B01HMZLMNY B01HMZLLHQ B01HMZLNNS B006WHHX50 B006WHI02K B01HMZMP6M B00LHJMT1G B07L48RB2K | M6: Columbia Men's Glennaker Rain Jacket | N6: 2476604011 | O6: Columbia | P6: 125368 | Q6: 116.71643 | R6: 5056449 | S6: 111.62081 | T6: 3228908 | U6: 196.46257 | V6: 43.4 | W6: 3434 | X6: 4.6 | AC6: TRUE
A7: COOFANDY | B7: 217903 | C7: 34.683333 | D7: 27.05 | E7: 45.57 | K7: B09WJHL6JM | L7: B0076R6LGM B0076R6L58 B00Q7B3ADK B0076R6MN4 B0076R6MVQ B00Q7B3CLU B0084AWSRQ B0084AWSW6 B0076R6MFM B00Q7B3GPM | M7: Columbia Men's Steens Mountain 2.0 Full Zip Fleece Jacket | N7: 2476496011 | O7: Columbia | P7: 125161 | Q7: 3.0798292 | R7: 4470455 | S7: 2.7334434 | T7: 3133896 | U7: 3.700757 | V7: 36.34 | W7: 724 | X7: 4.5 | Z7: 1 | AA7: Clothing, Shoes & Jewelry > Men > Clothing > Jackets & Coats > Active & Performance | AC7: TRUE
A8: PTEROMY | B8: 176786 | C8: 18.525 | D8: 18.18 | E8: 18.87 | K8: B07KW77JZ3 | L8: B07KW6Z47F B095NYS5BW B084H9BTWS B07KW6STT8 B07TPHRNNC B089SZMNX2 B07X1RG4YR B09KRNR6L9 B085VD4FF1 B08J6HGMW1 | M8: COOFANDY Men's Packable Rain Jacket Outdoor Waterproof Hooded Lightweight Classic Cycling Raincoat | N8: 2476604011 | O8: COOFANDY | P8: 111263 | Q8: 1.4910556 | R8: 3006152 | S8: 1.3507711 | T8: 1647881 | U8: 1.5146318 | V8: 27.05 | W8: 4280 | X8: 4.3 | Z8: 1 | AA8: Clothing, Shoes & Jewelry > Men > Shops > Big & Tall > Outerwear & Coats | AC8: TRUE
A9: SaphiRose | B9: 146643 | C9: 21.146667 | D9: 13.74 | E9: 28.5 | K9: B09K8PBQYX | L9: B07DH5CCMN B08YYL9DMS B09QZR1ZRC B09Y8XW2N8 B07T83MR5B B09QZRYV3S B0BJKS3S1K | M9: Cosowe Rain Ponchos for Adults Reusable, 2 Pcs Raincoats Emergency for Women Men with Hood and Drawstring | N9: 2476604011 | O9: Cosowe | P9: 108472 | Q9: 0.17586098 | R9: 1394835 | S9: 0.27018652 | T9: 784785 | U9: 0.29813514 | V9: 12.97 | W9: 4939 | X9: 4.4 | Z9: 6 | AA9: Clothing, Shoes & Jewelry > Men > Clothing > Jackets & Coats > Trench & Rain | AC9: TRUE
A10: Carhartt | B10: 130454 | C10: 94.33 | D10: 80.25 | E10: 103.53 | K10: B0BX3ZVL2V | L10: B0B62HGK2H B0B62J62J1 B0B62JLH7H B0B62HNYYR B0B62J98HG B0B62JR1VF B0CKMGLKBL B0CKMGHJT6 B0CPXNSHWJ B0CPXNFM5D | M10: SaphiRose Hooded Rain Poncho Waterproof Raincoat Jacket for Men Women Adults | N10: 2476604011 | O10: SaphiRose | P10: 99794 | R10: 1311144 | T10: 691766 | V10: 13.74 | W10: 2095 | X10: 4.6 | Z10: 10 | AA10: Clothing, Shoes & Jewelry > Men > Clothing > Jackets & Coats > Trench & Rain | AC10: TRUE
A11: Legendary Whitetails | B11: 128215 | C11: 71.85 | D11: 67.93 | E11: 75.77 | K11: B0BB1F7XYR | L11: B07539S9G3 B09WHLXYS6 B078MPMF6G B083F9XZHD B094QMN1ZC B0BBGT6Y7B B07TWDDVR1 B0BBGVBTH9 B0BBGRX8T9 B0753CYCL7 | M11: Anyoo Waterproof Rain Poncho Lightweight Reusable Hiking Hooded Coat Jacket for Outdoor Activities | N11: 2476604011 | O11: ANYOO | P11: 89355 | Q11: 1.3500868 | R11: 1383704 | S11: 1.1702846 | T11: 797150 | U11: 1.0665474 | V11: 15.51 | W11: 20352 | X11: 4.6 | Z11: 11 | AA11: Clothing, Shoes & Jewelry > Men > Clothing > Jackets & Coats > Trench & Rain | AC11: TRUE
A12: Outdoor Ventures | B12: 122418 | C12: 41.215 | D12: 33.51 | E12: 53.62 | K12: B0CK2PCJT4 | L12: B075ZJLCMR B075ZGJPMF B075ZG29D6 B075ZLYW8G B075ZGNCKC B014JP31SY B075ZD9L6X B07XYQHPD8 B075ZJ7BZV B08P3Z7BWJ | M12: Legendary Whitetails Men's Maplewood Hooded Shirt Jacket | N12: 7132366011 | O12: Legendary Whitetails | P12: 75240 | R12: 5200309 | T12: 1314746 | V12: 67.93 | W12: 13642 | X12: 4.6 | Z12: 31 | AA12: Clothing, Shoes & Jewelry > Men > Clothing > Jackets & Coats > Lightweight Jackets > Cotton | AC12: TRUE
A13: Cosowe | B13: 108472 | C13: 12.97 | D13: 12.97 | E13: 12.97 | K13: B09J22Q1JM | L13: B09J22Q1JM B00XH7I3K2 B00XH7HVLE B00XH7HVQY B00XH7I33E B073JQ4KVF B00XH7I3BQ B073JTH17L B00XH7I3XY B073JQV6TL | M13: Wrangler Authentics Men's Long Sleeve Sherpa Lined Shirt Jacket | N13: 2476495011 | O13: Wrangler | P13: 72937 | Q13: -0.45503926 | R13: 2138057 | S13: -0.45019117 | T13: 733413 | U13: -0.54771593 | V13: 29.34 | W13: 26427 | X13: 4.7
A14: ORORO | B14: 102749 | C14: 134.05333 | D14: 128.24 | E14: 143.53 | K14: B0CM13KV1C | L14: B079LKQ52C B079LT79M5 B079LPNXHF B079LLB7NV B079M1MW5N B09QJJTF16 B085YVGLX5 B09QJKGBG9 B08SX5BLNP B079LS5D8J | M14: Amazon Essentials Men's Full-Zip Polar Fleece Vest (Available in Big & Tall) | N14: 2562597011 | O14: Amazon Essentials | P14: 68335 | R14: 1078580 | T14: 1009027 | V14: 12.46 | W14: 12793 | X14: 4.5
A15: ANYOO | B15: 89355 | C15: 15.51 | D15: 15.51 | E15: 15.51 | K15: B08FBDSNFH | L15: B08F9P3C54 B08F9W2M7S B08F9SYXN3 B08F9VHBLV B08FB4TQBB B08F9Z9LH4 B08F9ZDT7M B08F9MZHS8 B09CPLW4L3 B08M9QB2F6 | M15: OTU Men's Lightweight Waterproof Hooded Rain Jacket Outdoor Raincoat Shell Jacket for Hiking Travel | N15: 2476604011 | O15: OTU | P15: 60989 | Q15: -0.081145009 | R15: 2244578 | S15: -0.036304863 | T15: 1029213 | U15: 0.26282254 | V15: 37.03 | W15: 13751 | X15: 4.5 | Z15: 1 | AA15: Clothing, Shoes & Jewelry > Men > Clothing > Jackets & Coats > Active & Performance > Shells | AC15: TRUE
A16: Levi's | B16: 89085 | C16: 52.855 | D16: 51.86 | E16: 53.85 | K16: B0B4NMTY5Q | L16: B0B4NKRWWL B0B4NJR5BV B0B4NSFV3Y B0B4NKSK4T B0B4NKKYVC B0B4NLXDP8 B0B4NMHVBL B0B4NKGKZP B0BHKNYX37 B0BHJN1C8M | M16: Derbars Men's Cotton Plaid Shirts Jacket Fleece Lined Flannel Shirts Sherpa Button Down Jackets with Hood for Men | N16: 2476496011 | O16: Derbars | P16: 60796 | Q16: 0.17906251 | R16: 2185693 | S16: 0.17511071 | T16: 819954 | U16: 0.32933969 | V16: 34.88 | W16: 2989 | X16: 4.5 | Z16: 13 | AA16: Clothing, Shoes & Jewelry > Men > Clothing > Jackets & Coats > Active & Performance | AC16: TRUE
A17: ZENTHACE | B17: 67995 | C17: 35.79 | D17: 35.41 | E17: 36.17 | K17: B083Z5R2RS | L17: B0B4F337W9 B0B4DZSCWW B0B4F2PY96 B0B4F2PZJP B0B4F3HZ6Z B0B4F2K8MZ B0B4DZ55SV B0B4F15NFW B0B4F49SKT B0B4F1XCV4 | M17: Carhartt Men's Loose Fit Washed Duck Sherpa-Lined Mock-Neck Vest | N17: 2562597011 | O17: Carhartt | P17: 59307 | Q17: 0.62743538 | R17: 4803985 | S17: 0.61322642 | T17: 714478 | U17: 0.32892515 | V17: 80.25 | W17: 6692 | X17: 4.7
A18: TACVASEN | B18: 62239 | C18: 42.345 | D18: 37.91 | E18: 46.78 | K18: B0CKDNT2V6 | L18: B078GMT64C B078GLSLBN B078GPYT9H B078GLS5NW B078GLLX3W B07DGQ9J67 B07DGSQ6D3 B078GP4PFR B07VRF3J36 B078H8B7N3 | M18: Champion Men's Jacket, Stadium Packable Wind and Water Resistant Jacket (Reg. Or Big & Tall) | N18: 7132372011 | O18: Champion | P18: 58951 | R18: 1373012 | T18: 715907 | V18: 25.15 | W18: 9925 | X18: 4.6 | Z18: 1 | AA18: Clothing, Shoes & Jewelry > Men > Clothing > Jackets & Coats > Down & Down Alternative | AC18: TRUE
A19: OTU | B19: 60989 | C19: 37.03 | D19: 37.03 | E19: 37.03 | K19: B0BHVSXL7D | L19: B019DYG83G B019DYG82W B019DYG9CG B019DYG4S0 B019DYG4P8 B019DYG4N0 B019DYGL6A B019DYG82M B019DYG4M6 B019DYGL60 | M19: Columbia Men's Steens Mountain Vest | N19: 2562597011 | O19: Columbia | P19: 58846 | Q19: 0.014901176 | R19: 1745998 | S19: -0.061395855 | T19: 883313 | U19: 0.051415396 | V19: 29.08 | W19: 18 | X19: 4.4 | Z19: 1 | AA19: Clothing, Shoes & Jewelry > Men > Clothing > Jackets & Coats > Vests | AC19: TRUE
A20: Derbars | B20: 60796 | C20: 34.88 | D20: 34.88 | E20: 34.88 | K20: B0C9V2VL33 | L20: B07P2JFZ34 B07NZ8B54K B07P3N8C1C B07P2JG113 B085YVKCNN B085YVSLDK B07P1DKBVK B07P3N4R36 B07NYB2PD3 B07P4NTMWD | M20: Amazon Essentials Men's Quarter-Zip Polar Fleece Jacket | N20: 2476496011 | O20: Amazon Essentials | P20: 55494 | Q20: 16.080332 | R20: 973850 | S20: 16.377146 | T20: 810298 | U20: 17.786905 | V20: 16.15 | W20: 6363 | X20: 4.5
A21: Champion | B21: 58951 | C21: 25.15 | D21: 25.15 | E21: 25.15 | K21: B088YDVJH8 | L21: B089VZPB2K B0814B6V66 B089W33ZMS B089VYYYKY B00GTW3RA8 B0814BJKZX B00GTW3PSW B0814B8VHQ B0B1PFY7SW B0B1QNXKYZ | M21: Columbia Men's Watertight II Rain Jacket | N21: 2476604011 | O21: Columbia | P21: 54227 | Q21: 319.86982 | R21: 3148517 | S21: 209.53273 | T21: 1169680 | U21: 860.32548 | V21: 67.56 | W21: 1669 | X21: 4.7 | Z21: 63 | AA21: Sports & Outdoors > Outdoor Recreation > Camping & Hiking > Clothing > Men > Jackets > Waterproof Jackets | AC21: TRUE
A22: COOY | B22: 48182 | C22: 12.59 | D22: 12.59 | E22: 12.59 | K22: B0CKFLQT7N | L22: B013KW3FH4 B00EUHCUIO B013KW38RQ B00EUHD56A B013KW39CU B00EUHD006 B00EUHD23Q B00EUHCMRS B07XG6VQVT B013KW3APG | M22: Legendary Whitetails Men's Journeyman Shirt Jacket, Flannel Lined Shacket for Men, Water-Resistant Coat Rugged Fall Clothing | N22: 7132374011 | O22: Legendary Whitetails | P22: 52975 | R22: 3977630 | T22: 1317045 | V22: 75.77 | W22: 18408 | X22: 4.4 | Z22: 17 | AA22: Clothing, Shoes & Jewelry > Men > Clothing > Jackets & Coats > Lightweight Jackets | AC22: TRUE
A23: URBANFIND | B23: 45562 | C23: 34.12 | D23: 34.12 | E23: 34.12 | K23: B0C2ZPLQ2C | L23: B00HQ4KSGE B00HQ4KS3W B00HQ4KSMI B00HQ4KSUU B00KIDCXU4 B00KIDCXNQ B00HQ4KRWY B00KIDCZ8E B00HQ4KUUS B00L3XLVBK | M23: Columbia Men's Ascender Softshell Front-zip Jacket | N23: 7132367011 | O23: Columbia | P23: 52918 | Q23: 6.6726113 | R23: 3595198 | S23: 6.8795579 | T23: 1401817 | U23: 7.9121952 | V23: 64.22 | W23: 125 | X23: 4.5 | AC23: TRUE
A24: Venustas | B24: 44415 | C24: 124.75 | D24: 111.54 | E24: 137.96 | K24: B0CNZSXQMD | L24: B01H50RF4Q B01H50RG8G B01H50RDLQ B01H50RCY4 B07SN1YB6D B07SHRWJ4X B08L884JKB B08L7VRDZ4 B08L8753NK B09GLW5G8L | M24: ORORO Men's Lightweight Heated Vest with Battery Pack | N24: 2562597011 | O24: ORORO | P24: 52904 | R24: 6736529 | T24: 406283 | V24: 130.39 | W24: 10486 | X24: 4.6 | Z24: 11 | AA24: Sports & Outdoors > Clothing > Men > Outerwear > Sweaters & Vests | AC24: TRUE
A25: Signature by Levi Strauss & Co. Gold | B25: 42718 | C25: 37.96 | D25: 37.96 | E25: 37.96 | K25: B0CQ7RS2PS | L25: B000FXXYG4 B07D937XQG | M25: Carhartt Men's Loose Fit Firm Duck Insulated Flannel-Lined Active Jacket | N25: 7132366011 | O25: Carhartt | P25: 51627 | R25: 5592823 | T25: 512396 | V25: 103.53 | W25: 22432 | X25: 4.7
A26: Srivb | B26: 42603 | C26: 59.79 | D26: 59.42 | E26: 60.16 | K26: B0C7261XXL | L26: B077TCHNW8 B076WXF1LV B076WWR8SB B077TDS2G6 B077TH4NG9 B076WYDPXK B08P537QSN B01ETP2O6Y B08P54B4Q7 B01ETP2O50 | M26: Levi's Men's Trucker Jacket (Also Available in Big & Tall) | N26: 2476495011 | O26: Levi's | P26: 49239 | Q26: 4.7941869 | R26: 2531448 | S26: 4.1436827 | T26: 1150349 | U26: 5.1650169 | V26: 51.86 | W26: 18949 | X26: 4.6 | Z26: 2 | AA26: Clothing, Shoes & Jewelry > Men > Clothing > Jackets & Coats > Lightweight Jackets > Denim | AC26: TRUE
A27: DEWBU | B27: 39771 | C27: 143.59 | D27: 143.59 | E27: 143.59 | K27: B07V7VD6VK | L27: B07SR5SH2M B07TDK396X B07V5SLWQX B07V6SGTKC B07V6T7VY7 B07V4PW4KT B0CKYJLL9X B07V5SLGNY | M27: COOY Rain Coats (2 Pack) - Reusable EVA Rain Ponchos for Adults Rain Jackets Raincoats for Men Women | N27: 2476604011 | O27: COOY | P27: 48182 | Q27: 2.8221482 | R27: 603762 | S27: 2.6875466 | T27: 338754 | U27: 3.5204569 | V27: 12.59 | W27: 90 | X27: 4.2 | Z27: 13 | AA27: Clothing, Shoes & Jewelry > Men > Clothing > Jackets & Coats > Trench & Rain | AC27: TRUE
A28: Under Armour | B28: 38444 | C28: 34.8 | D28: 34.8 | E28: 34.8 | K28: B074MY3BJL | L28: B06XKS972D B06XK97JQP B07NZMXP79 B06XK9C3C1 B07P1RCJB2 B099Z561T2 B099ZF9TKS B06XNK1DCH B06XKTR8P9 B06XKYKPZT | M28: URBANFIND Men's Slim Fit Lightweight Sportswear Jacket Casual Bomber Jacket | N28: 7132372011 | O28: URBANFIND | P28: 45562 | Q28: -0.39906091 | R28: 1585327 | S28: -0.42704954 | T28: 687672 | U28: -0.44792484 | V28: 34.12 | W28: 8626 | X28: 4.5 | Z28: 29 | AA28: Clothing, Shoes & Jewelry > Men > Clothing > Jackets & Coats > Lightweight Jackets | AC28: TRUE
A29: LONDON FOG | B29: 37194 | C29: 44.12 | D29: 44.12 | E29: 44.12 | K29: B09LKNT3H7 | L29: B085YV9D7R B085YVPS76 B085YVT4LF B085YVT4MZ B085YVRZ3H B085YVLXX4 B085YVNZ17 B085YVT4MJ B085YVZN7F B085YVD295 | M29: Amazon Essentials Men's Long-Sleeve Polar Fleece Shirt Jacket | N29: 2476496011 | O29: Amazon Essentials | P29: 44720 | Q29: -0.28235577 | R29: 1030271 | S29: -0.22265874 | T29: 868831 | U29: -0.18524051 | V29: 19.43 | W29: 5961 | X29: 4.5
A30: TEZO | B30: 32552 | C30: 38.73 | D30: 38.73 | E30: 38.73 | K30: B0B49K9RK4 | L30: B07VGQTMYD B07VBD88BB B07VBD87YB B07VQHGCVY B07VMDZ1DZ B07VMDZC7F B07VFMQ59K B07VHLRSPG B0B3X32X9W B07VPH7GTM | M30: TACVASEN Men's Bomber Jacket Lightweight Casual Spring Fall Windbreaker Zip Up Coat with Pocket | N30: 7132372011 | O30: TACVASEN | P30: 42770 | Q30: 2.1294359 | R30: 1632708 | S30: 2.3186201 | T30: 834570 | U30: 2.143082 | V30: 37.91 | W30: 6645 | X30: 4.4 | Z30: 1 | AA30: Clothing, Shoes & Jewelry > Men > Clothing > Jackets & Coats > Lightweight Jackets | AC30: TRUE
A31: ANTVEE | B31: 32168 | C31: 13.94 | D31: 13.94 | E31: 13.94 | K31: B088XZH4GT | L31: B07XLNTK57 B07PX3Y37Z B07XTZLGVZ B07XTZY32R B07Q1K4HXL B07PX3XFHF B07D1M9DWG B07XTYMRPW B07Q2WTK7B B09JYSQMZS | M31: Signature by Levi Strauss & Co. Gold Label Men's Signature Trucker Jacket | N31: 2476495011 | O31: Signature by Levi Strauss & Co. Gold | P31: 42718 | Q31: -0.10261958 | R31: 1645449 | S31: -0.089232518 | T31: 622323 | U31: -0.23171707 | V31: 37.96 | W31: 12305 | X31: 4.6 | Z31: 1 | AA31: Clothing, Shoes & Jewelry > Men > Clothing > Jackets & Coats > Lightweight Jackets > Denim | AC31: TRUE
A32: TBMPOY | B32: 29707 | C32: 35.3 | D32: 35.3 | E32: 35.3 | K32: B0CMFWCHTD | L32: B08P53TKVD B072MFYGSS B08P52ZKNH B072JV2MPW B077T7YCLH B071JML8P2 B077TCDV6D B077TC99HF B08P53R4DX B08P53CYZH | M32: Levi's Men's Sherpa Trucker Jacket (Also Available in Big & Tall) | N32: 2476495011 | O32: Levi's | P32: 39846 | R32: 2146257 | T32: 1067657 | V32: 53.85 | W32: 17737 | X32: 4.7 | Z32: 20 | AA32: Clothing, Shoes & Jewelry > Men > Clothing > Jackets & Coats > Lightweight Jackets | AC32: TRUE
A33: HOOD CREW | B33: 28788 | C33: 53.35 | D33: 53.35 | E33: 53.35 | K33: B0935RTT2L | L33: B0935RTT2L B07KXJCXFZ | M33: DEWBU Heated Jacket for Men with 12V Battery Pack Winter Outdoor Soft Shell Electric Heating Coat | N33: 7132367011 | O33: DEWBU | P33: 39771 | Q33: -0.5204153 | R33: 5343926 | S33: -0.56358501 | T33: 352154 | U33: -0.70605798 | V33: 143.59 | W33: 6452 | X33: 4.4
A34: ALBRY | B34: 28012 | C34: 9.6 | D34: 9.6 | E34: 9.6 | K34: B09JNSP9F5 | L34: B09JNL4HG5 B09JNKLTF6 B09JNKWGR5 B09JNKS138 B09JNKGQNT B09JNJMKD9 B09JNH9RH6 B09JNKG5PC B09JNKJGZB B09JNKM6J9 | M34: Under Armour Men's Armourfleece 1/4 Zip | N34: 2476496011 | O34: Under Armour | P34: 38444 | Q34: 0.98913437 | R34: 1413325 | S34: 1.249221 | T34: 440138 | U34: 0.46541701 | V34: 34.8 | W34: 869 | X34: 4.6 | Z34: 28 | AA34: Clothing, Shoes & Jewelry > Men > Clothing > Jackets & Coats > Fleece | AC34: TRUE
A35: MACHLAB | B35: 27828 | C35: 41.75 | D35: 41.75 | E35: 41.75 | K35: B0CRVCYZMS | L35: B07ZF5VCGH B07ZFHW4P1 B07ZFJ1XRJ B07ZFJ62XN B07ZFJ4DS4 B0BZ7YCR48 B0BZ7Y9HH4 B0BM3W1SPV B0B3N9NBN3 B0BM37BKVV | M35: Outdoor Ventures Men's Rain Jacket Waterproof Lightweight Packable Rain Shell Raincoat with Hood for Golf Hiking Travel | N35: 2476604011 | O35: Outdoor Ventures | P35: 38061 | R35: 1355370 | T35: 609294 | V35: 35.62 | W35: 966 | X35: 4.5 | Z35: 10 | AA35: Sports & Outdoors > Outdoor Recreation > Outdoor Clothing > Men > Jackets & Coats > Raincoats & Jackets | AC35: TRUE
A36: ZITY | B36: 27000 | C36: 39.97 | D36: 39.97 | E36: 39.97 | K36: B07TYX35GG | L36: B083SCB5ZG B07TTNTK17 B083SD6XTM B08PT8HJVH B083SC7XHN B083SB84ZJ B0B97C943X B08PT9KGY2 B08PT8QS48 B07TZ13G17 | M36: ZENTHACE Men's Warm Sherpa Lined Fleece Plaid Flannel Shirt Jacket(All Sherpa Fleece Lined) | N36: 2476496011 | O36: ZENTHACE | P36: 37934 | Q36: 0.05410287 | R36: 1400958 | S36: 0.0064252227 | T36: 461394 | U36: 0.20416216 | V36: 35.41 | W36: 7209 | X36: 4.6 | Z36: 18 | AA36: Clothing, Shoes & Jewelry > Men > Clothing > Jackets & Coats > Active & Performance | AC36: TRUE
A37: Gary Com | B37: 26900 | C37: 37.96 | D37: 37.96 | E37: 37.96 | K37: B08224J2ZG | L37: B005EVQ4AA B005EVQ49G B005EVQ3EW B005EVQ48W B003DTLU9K B005EVQ3DS B005EVQ3CY B005EVQ4BY B005EVQ4A0 B005EVQ3EC | M37: London Fog Men's Auburn Zip-Front Golf Jacket (Regular & Big-Tall Sizes) | N37: 7132374011 | O37: LONDON FOG | P37: 37194 | Q37: -0.1159441 | R37: 1629077 | S37: 0.064222011 | T37: 695605 | U37: -0.13963726 | V37: 44.12 | W37: 13435 | X37: 4.5 | Z37: 10 | AA37: Clothing, Shoes & Jewelry > Men > Clothing > Jackets & Coats > Lightweight Jackets > Cotton | AC37: TRUE
A38: Dickies | B38: 26842 | C38: 60.12 | D38: 60.12 | E38: 60.12 | K38: B0D1YMGG9F | L38: B073GBHPRH B073G9N87Y B0738GM37J B0738HBW7G B0738G3VBG B07P1DKK1V B073GB8RWM B07NZ8B9CC B07P3N4R3P B073GB8RWQ | M38: Amazon Essentials Men's Full-Zip Fleece Jacket - Discontinued Colors | N38: 2476496011 | O38: Amazon Essentials | P38: 35005 | R38: 315456 | T38: 431816 | V38: 8.78 | W38: 13643 | X38: 4.5 | Z38: 48 | AA38: Clothing, Shoes & Jewelry > Men > Clothing > Jackets & Coats > Fleece | AC38: TRUE
A39: MAGNIVIT | B39: 26062 | C39: 44.73 | D39: 44.73 | E39: 44.73 | K39: B0CQ7RTZ5B | L39: B07BN4C7XP B07BN72SZ5 B07BN78SN2 B07BN69F9L B07BN78SNF B07BN7GC7Y B07C8Z5TGC B07C8YYFMV B07BN7G9GD B07BN7GC8Q | M39: Amazon Essentials Men's Lightweight Water-Resistant Packable Hooded Puffer Jacket | N39: 2476602011 | O39: Amazon Essentials | P39: 33028 | R39: 1222006 | T39: 572834 | V39: 38.48 | W39: 11355 | X39: 4.5 | Z39: 46 | AA39: Clothing, Shoes & Jewelry > Men > Clothing > Jackets & Coats > Active & Performance | AC39: TRUE
A40: DOACE | B40: 25982 | C40: 50.7 | D40: 50.7 | E40: 50.7 | K40: B09BD894V9 | L40: B07XBLV99D B08136C47G B08DCS47RR B09Z7QP5BF B0C6JNFTY7 B0C9QNBDCR B08DCHFSKC B07X9MN14C B09Z7QZW16 B08DCT239P | M40: TEZO Mens Rain Jacket Waterproof with Hooded Hiking Coat Lightweight Windbreaker | N40: 7132372011 | O40: TEZO | P40: 32552 | Q40: -0.18897775 | R40: 1245231 | S40: -0.19916819 | T40: 585573 | U40: 0.067120919 | V40: 38.73 | W40: 4458 | X40: 4.4 | Z40: 12 | AA40: Sports & Outdoors > Sports & Fitness > Clothing > Men > Jackets & Coats > Shells | AC40: TRUE
...
